Workbook

Sheet مواد المخزون
A1: مادة مخزون | B1: Name EN | C1: Code | D1: نوع المادة | E1: وحدة القياس | F1: الكمية الحالية | G1: حد التنبيه | H1: الكلفة التقديرية للوحدة | I1: المورد المفضل | J1: ملاحظات
A2: بطاطا | B2: Potato | C2: ING-VEG-POTATO | D2: مكوّن | E2: كغ | H2: 7000 | J2: مرجع سعر المشروع: 7,000 ل.س/كغ.
A3: بصل | B3: Onion | C3: ING-VEG-ONION | D3: مكوّن | E3: كغ | H3: 12000 | J3: مرجع سعر المشروع: 12,000 ل.س/كغ.
A4: كوسا | B4: Zucchini | C4: ING-VEG-ZUCCHINI | D4: مكوّن | E4: كغ | H4: 8000 | J4: مرجع سعر المشروع: 8,000 ل.س/كغ.
A5: ليمون | B5: Lemon | C5: ING-FRT-LEMON | D5: مكوّن | E5: كغ | H5: 30000 | J5: مرجع سعر المشروع: 30,000 ل.س/كغ.
A6: بندورة | B6: Tomato | C6: ING-VEG-TOMATO | D6: مكوّن | E6: كغ | H6: 9000 | J6: مرجع سعر المشروع: 9,000 ل.س/كغ.
A7: فاصوليا خضراء | B7: Green Beans | C7: ING-VEG-GREENBEAN | D7: مكوّن | E7: كغ | H7: 15500 | J7: مرجع سعر المشروع: 15,500 ل.س/كغ.
A8: فجل | B8: Radish | C8: ING-VEG-RADISH | D8: مكوّن | E8: عبوة | H8: 2000 | J8: العبوة المقصودة جرزة، نحو 4–5 حبات.
A9: باذنجان | B9: Eggplant | C9: ING-VEG-EGGPLANT | D9: مكوّن | E9: كغ | H9: 5000 | J9: مرجع سعر المشروع: 5,000 ل.س/كغ.
A10: فليفلة حارة | B10: Hot Pepper | C10: ING-VEG-HOTPEPPER | D10: مكوّن | E10: كغ | H10: 10000 | J10: مرجع سعر المشروع: 10,000 ل.س/كغ.
A11: فليفلة حلوة | B11: Bell Pepper | C11: ING-VEG-BELLPEPPER | D11: مكوّن | E11: كغ | H11: 9000 | J11: مرجع سعر المشروع: 9,000 ل.س/كغ.
A12: خيار / بعجور | B12: Cucumber | C12: ING-VEG-CUCUMBER | D12: مكوّن | E12: كغ | H12: 5000 | J12: مرجع السعر سُجّل باسم بعجور: 5,000 ل.س/كغ.
A13: بازيلا خضراء | B13: Green Peas | C13: ING-VEG-GREENPEAS | D13: مكوّن | E13: كغ | H13: 8000 | J13: مرجع سعر المشروع: 8,000 ل.س/كغ.
... A17: جزر | B17: Carrot | C17: ING-VEG-CARROT | D17: مكوّن | E17: كغ | H17: 9000 | J17: مرجع سعر المشروع: 9,000 ل.س/كغ.
A18: شمندر | B18: Beetroot | C18: ING-VEG-BEET | D18: مكوّن | E18: كغ
A19: سبانخ | B19: Spinach | C19: ING-VEG-SPINACH | D19: مكوّن | E19: كغ
A20: كرفس | B20: Celery | C20: ING-HERB-CELERY | D20: مكوّن | E20: عبوة
A21: بصل أخضر | B21: Spring Onion | C21: ING-HERB-SPRINGONION | D21: مكوّن | E21: عبوة
A22: ثوم طازج | B22: Fresh Garlic | C22: ING-VEG-GARLIC | D22: مكوّن | E22: كغ | H22: 8000 | J22: مرجع سعر المشروع: 8,000 ل.س/كغ.
A23: فطر طازج | B23: Fresh Mushroom | C23: ING-VEG-MUSHROOM | D23: مكوّن | E23: كغ
A24: ذرة حلوة | B24: Sweet Corn | C24: ING-VEG-SWEETCORN | D24: مكوّن | E24: كغ
A25: عرانيس ذرة | B25: Corn on the Cob | C25: ING-VEG-CORNCOB | D25: مكوّن | E25: قطعة
A26: ورق عنب | B26: Grape Leaves | C26: ING-VEG-GRAPELEAF | D26: مكوّن | E26: كغ
A27: نعنع طازج | B27: Fresh Mint | C27: ING-HERB-MINT | D27: مكوّن | E27: عبوة | H27: 1500 | J27: سُجّل السعر لجرزة نعنع أو بقدونس: 1,500 ل.س.
A28: بقدونس | B28: Parsley | C28: ING-HERB-PARSLEY | D28: مكوّن | E28: عبوة | H28: 1500 | J28: سُجّل السعر لجرزة نعنع أو بقدونس: 1,500 ل.س.
A29: كزبرة خضراء | B29: Fresh Coriander | C29: ING-HERB-CILANTRO | D29: مكوّن | E29: عبوة
A30: حبق / ريحان | B30: Fresh Basil | C30: ING-HERB-BASIL | D30: مكوّن | E30: عبوة | J30: أساسي لسندويشات حبق ومشروب الجن بالحبق.
A31: زعتر بري طازج | B31: Fresh Wild Thyme | C31: ING-HERB-WILDTHYME | D31: مكوّن | E31: عبوة | H31: 3000 | J31: مرجع سعر المشروع: 3,000 ل.س/جرزة.
A32: ترخون | B32: Tarragon | C32: ING-HERB-TARRAGON | D32: مكوّن | E32: عبوة | H32: 3000 | J32: مرجع سعر المشروع: 3,000 ل.س/جرزة.
A33: شبت | B33: Dill | C33: ING-HERB-DILL | D33: مكوّن | E33: عبوة
A34: تفاح | B34: Apple | C34: ING-FRT-APPLE | D34: مكوّن | E34: كغ | J34: للعصير، شاي التفاح، السموذي والحلويات.
A35: بطيخ أحمر | B35: Watermelon | C35: ING-FRT-WATERMELON | D35: مكوّن | E35: كغ | J35: لعصير البطيخ.
A36: رمان | B36: Pomegranate | C36: ING-FRT-POMEGRANATE | D36: مكوّن | E36: كغ
A37: برتقال | B37: Orange | C37: ING-FRT-ORANGE | D37: مكوّن | E37: كغ
A38: موز | B38: Banana | C38: ING-FRT-BANANA | D38: مكوّن | E38: كغ | J38: للميلك شيك والسموذي.
A39: فريز | B39: Strawberry | C39: ING-FRT-STRAWBERRY | D39: مكوّن | E39: كغ | J39: للميلك شيك والسموذي.
A40: مشمش | B40: Apricot | C40: ING-FRT-APRICOT | D40: مكوّن | E40: كغ
A41: تين | B41: Fig | C41: ING-FRT-FIG | D41: مكوّن | E41: كغ
A42: عنب | B42: Grapes | C42: ING-FRT-GRAPES | D42: مكوّن | E42: كغ | J42: للعصير، الجلاب، الدبس والمنتجات الموسمية.
A43: لبن مبستر | B43: Pasteurized Yogurt | C43: ING-DAIRY-YOGURT-PAST | D43: مكوّن | E43: كغ | H43: 15000 | J43: مرجع سعر المشروع: 15,000 ل.س/كغ.
...

Sheet دليل الإدخال
A1: دليل إعداد مواد المخزون
A2: عدد المواد المقترحة | B2: 252
A3: مبدأ القائمة | B3: مواد خام، مشروبات جاهزة، تغليف، تنظيف ومستهلكات تشغيل. المنتجات المباعة مثل كابتشينو أو سندويش لا تُضاف هنا؛ تُربط بهذه المواد عبر وصفة المنتج.
A4: الأكواد | B4: أكواد مقترحة وليست بيانات سابقة. يمكن اعتمادها كما هي أو تعديلها قبل الإدخال.
A5: الكمية الحالية | B5: تُركت فارغة لأنها تحتاج جرداً فعلياً. أدخل رصيد الافتتاح بعد العد أو عبر حركة مخزون.
A6: حد التنبيه | B6: تُرك فارغاً. الأفضل تحديده لاحقاً حسب الاستهلاك وزمن التوريد.
A7: الكلفة التقديرية | B7: معبأة فقط عندما كان السعر معروفاً. عند تحويل سعر عبوة إلى كغ/لتر، تم توضيح الحساب في الملاحظات.
A8: المورد المفضل | B8: تُرك فارغاً لعدم وجود أسماء موردين مؤكدة.
A9: ملاحظة المنتجات المحضّرة | B9: الحمص، المحمّرة، الفلافل، الشنينة والصوصات المحضّرة تُضاف كمخزون مستقل فقط إذا كانت تُشترى جاهزة أو تُدار كدفعات إنتاج.
A10: ملاحظة الأسعار | B10: الأسعار تاريخية من مراجع المشروع، ويجب تحديثها قبل الشراء أو احتساب الهامش.
A12: نوع المادة — القيمة الظاهرة | B12: القيمة التقنية في النظام
A13: مكوّن | B13: ingredient
A14: مشروبات ومستلزمات | B14: drink_supply
A15: تغليف | B15: packaging
... A30: أخرى | B30: other

Sheet المصادر
A1: المصدر | B1: الاستخدام
A2: https://github.com/Maximad/hub/blob/main/core/models.py | B2: الحقول والخيارات الحالية لنموذج InventoryItem.
A3: Morning picture request.txt — مرجع الأسعار | B3: الأسعار المعروفة للخضار، الألبان، الصوصات، البهارات، المشروبات والتنظيف.
A4: Hub / Masharib project conversations | B4: منتجات مشاريب، سفرة، السندويشات، Black Barrel، الكيش، المازة والأطباق اليومية.
A5: deep-research-report.md | B5: المشروبات المحلية: المتة، الجلاب، الزهورات، دبس العنب، الشنينة والكركديه.
A6: Hub_Sueda_Concept_Note_AR.docx | B6: نطاق التشغيل: مشاريب، سناك، مختبر الطعام والفعاليات.

Sheet وصفات المنتجات
A1: حالة الاستيراد | B1: اسم المنتج | C1: مفتاح المنتج | D1: مادة المخزون | E1: كود مادة المخزون | F1: الكمية المدخلة | G1: وحدة الإدخال | H1: وحدة المخزون | I1: الكمية الموحّدة | J1: نسبة الهدر % | K1: نشط | L1: كلفة وحدة المخزون | M1: كلفة السطر | N1: ملاحظات | O1: التحقق
A2: جاهز للاستيراد | B2: شاي عادي | C2: =IFERROR(VLOOKUP(B2,'مراجع الوصفات'!$A$2:$D$79,2,FALSE),"") -> regular_tea | D2: شاي أحمد عادي – ظرف | E2: =IFERROR(VLOOKUP(D2,'مراجع الوصفات'!$F$2:$I$253,2,FALSE),"") -> DRK-TEA-AHMAD-BAG | F2: 1 | G2: حصة | H2: =IFERROR(VLOOKUP(D2,'مراجع الوصفات'!$F$2:$I$253,3,FALSE),"") -> حصة | I2: =IF(OR(F2="",G2="",H2=""),"",IF(G2=H2,F2,IF(AND(G2="غ",H2="كغ"),F2/1000,IF(AND(G2="كغ",H2="غ"),F2*1000,IF(AND(G2="مل",H2="لتر"),F2/1000,IF(AND(G2="لتر",H2="مل"),F2*1000,"خطأ وحدة")))))) -> 1 | J2: 0 | K2: نعم | L2: =IFERROR(VLOOKUP(D2,'مراجع الوصفات'!$F$2:$I$253,4,FALSE),"") -> 420 | M2: =IF(OR(I2="",NOT(ISNUMBER(I2)),L2=""),"",I2*L2*(1+J2/100)) -> 420 | N2: لا يشمل السكر لأنه خيار متغيّر. | O2: =IF(AND(B2="",D2="",F2=""),"",IF(A2="تجاهل","تجاهل",IF(OR(B2="",D2="",F2="",G2="",H2=""),"ناقص",IF(NOT(ISNUMBER(I2)),"خطأ وحدة",IF(OR(J2<0,J2>100),"خطأ هدر","صالح"))))) -> صالح
A3: جاهز للاستيراد | B3: شاي مع نعنع | C3: =IFERROR(VLOOKUP(B3,'مراجع الوصفات'!$A$2:$D$79,2,FALSE),"") -> mint_tea | D3: شاي أحمد عادي – ظرف | E3: =IFERROR(VLOOKUP(D3,'مراجع الوصفات'!$F$2:$I$253,2,FALSE),"") -> DRK-TEA-AHMAD-BAG | F3: 1 | G3: حصة | H3: =IFERROR(VLOOKUP(D3,'مراجع الوصفات'!$F$2:$I$253,3,FALSE),"") -> حصة | I3: =IF(OR(F3="",G3="",H3=""),"",IF(G3=H3,F3,IF(AND(G3="غ",H3="كغ"),F3/1000,IF(AND(G3="كغ",H3="غ"),F3*1000,IF(AND(G3="مل",H3="لتر"),F3/1000,IF(AND(G3="لتر",H3="مل"),F3*1000,"خطأ وحدة")))))) -> 1 | J3: 0 | K3: نعم | L3: =IFERROR(VLOOKUP(D3,'مراجع الوصفات'!$F$2:$I$253,4,FALSE),"") -> 420 | M3: =IF(OR(I3="",NOT(ISNUMBER(I3)),L3=""),"",I3*L3*(1+J3/100)) -> 420 | O3: =IF(AND(B3="",D3="",F3=""),"",IF(A3="تجاهل","تجاهل",IF(OR(B3="",D3="",F3="",G3="",H3=""),"ناقص",IF(NOT(ISNUMBER(I3)),"خطأ وحدة",IF(OR(J3<0,J3>100),"خطأ هدر","صالح"))))) -> صالح
A4: جاهز للاستيراد | B4: شاي مع نعنع | C4: =IFERROR(VLOOKUP(B4,'مراجع الوصفات'!$A$2:$D$79,2,FALSE),"") -> mint_tea | D4: نعنع طازج | E4: =IFERROR(VLOOKUP(D4,'مراجع الوصفات'!$F$2:$I$253,2,FALSE),"") -> ING-HERB-MINT | F4: 0.05 | G4: عبوة | H4: =IFERROR(VLOOKUP(D4,'مراجع الوصفات'!$F$2:$I$253,3,FALSE),"") -> عبوة | I4: =IF(OR(F4="",G4="",H4=""),"",IF(G4=H4,F4,IF(AND(G4="غ",H4="كغ"),F4/1000,IF(AND(G4="كغ",H4="غ"),F4*1000,IF(AND(G4="مل",H4="لتر"),F4/1000,IF(AND(G4="لتر",H4="مل"),F4*1000,"خطأ وحدة")))))) -> 0.05 | J4: 0 | K4: نعم | L4: =IFERROR(VLOOKUP(D4,'مراجع الوصفات'!$F$2:$I$253,4,FALSE),"") -> 1500 | M4: =IF(OR(I4="",NOT(ISNUMBER(I4)),L4=""),"",I4*L4*(1+J4/100)) -> 75 | N4: تقدير: 5% من عبوة نعنع؛ راجع حجم العبوة الفعلي. | O4: =IF(AND(B4="",D4="",F4=""),"",IF(A4="تجاهل","تجاهل",IF(OR(B4="",D4="",F4="",G4="",H4=""),"ناقص",IF(NOT(ISNUMBER(I4)),"خطأ وحدة",IF(OR(J4<0,J4>100),"خطأ هدر","صالح"))))) -> صالح
A5: جاهز للاستيراد | B5: شاي مع ميرمية | C5: =IFERROR(VLOOKUP(B5,'مراجع الوصفات'!$A$2:$D$79,2,FALSE),"") -> sage_tea | D5: شاي أحمد عادي – ظرف | E5: =IFERROR(VLOOKUP(D5,'مراجع الوصفات'!$F$2:$I$253,2,FALSE),"") -> DRK-TEA-AHMAD-BAG | F5: 1 | G5: حصة | H5: =IFERROR(VLOOKUP(D5,'مراجع الوصفات'!$F$2:$I$253,3,FALSE),"") -> حصة | I5: =IF(OR(F5="",G5="",H5=""),"",IF(G5=H5,F5,IF(AND(G5="غ",H5="كغ"),F5/1000,IF(AND(G5="كغ",H5="غ"),F5*1000,IF(AND(G5="مل",H5="لتر"),F5/1000,IF(AND(G5="لتر",H5="مل"),F5*1000,"خطأ وحدة")))))) -> 1 | J5: 0 | K5: نعم | L5: =IFERROR(VLOOKUP(D5,'مراجع الوصفات'!$F$2:$I$253,4,FALSE),"") -> 420 | M5: =IF(OR(I5="",NOT(ISNUMBER(I5)),L5=""),"",I5*L5*(1+J5/100)) -> 420 | O5: =IF(AND(B5="",D5="",F5=""),"",IF(A5="تجاهل","تجاهل",IF(OR(B5="",D5="",F5="",G5="",H5=""),"ناقص",IF(NOT(ISNUMBER(I5)),"خطأ وحدة",IF(OR(J5<0,J5>100),"خطأ هدر","صالح"))))) -> صالح
A6: جاهز للاستيراد | B6: شاي مع ميرمية | C6: =IFERROR(VLOOKUP(B6,'مراجع الوصفات'!$A$2:$D$79,2,FALSE),"") -> sage_tea | D6: ميرمية مجففة | E6: =IFERROR(VLOOKUP(D6,'مراجع الوصفات'!$F$2:$I$253,2,FALSE),"") -> ING-HERB-SAGE | F6: 2 | G6: غ | H6: =IFERROR(VLOOKUP(D6,'مراجع الوصفات'!$F$2:$I$253,3,FALSE),"") -> كغ | I6: =IF(OR(F6="",G6="",H6=""),"",IF(G6=H6,F6,IF(AND(G6="غ",H6="كغ"),F6/1000,IF(AND(G6="كغ",H6="غ"),F6*1000,IF(AND(G6="مل",H6="لتر"),F6/1000,IF(AND(G6="لتر",H6="مل"),F6*1000,"خطأ وحدة")))))) -> 0.002 | J6: 0 | K6: نعم | L6: =IFERROR(VLOOKUP(D6,'مراجع الوصفات'!$F$2:$I$253,4,FALSE),"") | M6: =IF(OR(I6="",NOT(ISNUMBER(I6)),L6=""),"",I6*L6*(1+J6/100)) | N6: جرعة تقديرية 2غ. | O6: =IF(AND(B6="",D6="",F6=""),"",IF(A6="تجاهل","تجاهل",IF(OR(B6="",D6="",F6="",G6="",H6=""),"ناقص",IF(NOT(ISNUMBER(I6)),"خطأ وحدة",IF(OR(J6<0,J6>100),"خطأ هدر","صالح"))))) -> صالح
A7: جاهز للاستيراد | B7: شاي إيرل غراي | C7: =IFERROR(VLOOKUP(B7,'مراجع الوصفات'!$A$2:$D$79,2,FALSE),"") -> earl_grey_tea | D7: شاي أحمد إيرل غراي – ظرف | E7: =IFERROR(VLOOKUP(D7,'مراجع الوصفات'!$F$2:$I$253,2,FALSE),"") -> DRK-TEA-EARLGREY-BAG | F7: 1 | G7: حصة | H7: =IFERROR(VLOOKUP(D7,'مراجع الوصفات'!$F$2:$I$253,3,FALSE),"") -> حصة | I7: =IF(OR(F7="",G7="",H7=""),"",IF(G7=H7,F7,IF(AND(G7="غ",H7="كغ"),F7/1000,IF(AND(G7="كغ",H7="غ"),F7*1000,IF(AND(G7="مل",H7="لتر"),F7/1000,IF(AND(G7="لتر",H7="مل"),F7*1000,"خطأ وحدة")))))) -> 1 | J7: 0 | K7: نعم | L7: =IFERROR(VLOOKUP(D7,'مراجع الوصفات'!$F$2:$I$253,4,FALSE),"") -> 585 | M7: =IF(OR(I7="",NOT(ISNUMBER(I7)),L7=""),"",I7*L7*(1+J7/100)) -> 585 | O7: =IF(AND(B7="",D7="",F7=""),"",IF(A7="تجاهل","تجاهل",IF(OR(B7="",D7="",F7="",G7="",H7=""),"ناقص",IF(NOT(ISNUMBER(I7)),"خطأ وحدة",IF(OR(J7<0,J7>100),"خطأ هدر","صالح"))))) -> صالح
A8: جاهز للاستيراد | B8: شاي فواكه / منكه | C8: =IFERROR(VLOOKUP(B8,'مراجع الوصفات'!$A$2:$D$79,2,FALSE),"") -> fruit_flavored_tea | D8: شاي أحمد فواكه – ظرف | E8: =IFERROR(VLOOKUP(D8,'مراجع الوصفات'!$F$2:$I$253,2,FALSE),"") -> DRK-TEA-FRUIT-BAG | F8: 1 | G8: حصة | H8: =IFERROR(VLOOKUP(D8,'مراجع الوصفات'!$F$2:$I$253,3,FALSE),"") -> حصة | I8: =IF(OR(F8="",G8="",H8=""),"",IF(G8=H8,F8,IF(AND(G8="غ",H8="كغ"),F8/1000,IF(AND(G8="كغ",H8="غ"),F8*1000,IF(AND(G8="مل",H8="لتر"),F8/1000,IF(AND(G8="لتر",H8="مل"),F8*1000,"خطأ وحدة")))))) -> 1 | J8: 0 | K8: نعم | L8: =IFERROR(VLOOKUP(D8,'مراجع الوصفات'!$F$2:$I$253,4,FALSE),"") -> 1325 | M8: =IF(OR(I8="",NOT(ISNUMBER(I8)),L8=""),"",I8*L8*(1+J8/100)) -> 1325 | N8: استخدم شاي الفواكه؛ بدّل الكود إلى الشاي المنكّه إذا كان المنتج المقصود. | O8: =IF(AND(B8="",D8="",F8=""),"",IF(A8="تجاهل","تجاهل",IF(OR(B8="",D8="",F8="",G8="",H8=""),"ناقص",IF(NOT(ISNUMBER(I8)),"خطأ وحدة",IF(OR(J8<0,J8>100),"خطأ هدر","صالح"))))) -> صالح
A9: جاهز للاستيراد | B9: زهورات | C9: =IFERROR(VLOOKUP(B9,'مراجع الوصفات'!$A$2:$D$79,2,FALSE),"") -> zhourat | D9: زهورات مشكلة | E9: =IFERROR(VLOOKUP(D9,'مراجع الوصفات'!$F$2:$I$253,2,FALSE),"") -> DRK-HERBAL-ZHOURAT | F9: 5 | G9: غ | H9: =IFERROR(VLOOKUP(D9,'مراجع الوصفات'!$F$2:$I$253,3,FALSE),"") -> كغ | I9: =IF(OR(F9="",G9="",H9=""),"",IF(G9=H9,F9,IF(AND(G9="غ",H9="كغ"),F9/1000,IF(AND(G9="كغ",H9="غ"),F9*1000,IF(AND(G9="مل",H9="لتر"),F9/1000,IF(AND(G9="لتر",H9="مل"),F9*1000,"خطأ وحدة")))))) -> 0.005 | J9: 0 | K9: نعم | L9: =IFERROR(VLOOKUP(D9,'مراجع الوصفات'!$F$2:$I$253,4,FALSE),"") | M9: =IF(OR(I9="",NOT(ISNUMBER(I9)),L9=""),"",I9*L9*(1+J9/100)) | N9: تقدير 5غ للكاسة. | O9: =IF(AND(B9="",D9="",F9=""),"",IF(A9="تجاهل","تجاهل",IF(OR(B9="",D9="",F9="",G9="",H9=""),"ناقص",IF(NOT(ISNUMBER(I9)),"خطأ وحدة",IF(OR(J9<0,J9>100),"خطأ هدر","صالح"))))) -> صالح
A10: جاهز للاستيراد | B10: هوت شوكليت بالماء | C10: =IFERROR(VLOOKUP(B10,'مراجع الوصفات'!$A$2:$D$79,2,FALSE),"") -> hot_chocolate_water | D10: هوت شوكليت – ظرف | E10: =IFERROR(VLOOKUP(D10,'مراجع الوصفات'!$F$2:$I$253,2,FALSE),"") -> DRK-CHOCO-SACHET | F10: 1 | G10: حصة | H10: =IFERROR(VLOOKUP(D10,'مراجع الوصفات'!$F$2:$I$253,3,FALSE),"") -> حصة | I10: =IF(OR(F10="",G10="",H10=""),"",IF(G10=H10,F10,IF(AND(G10="غ",H10="كغ"),F10/1000,IF(AND(G10="كغ",H10="غ"),F10*1000,IF(AND(G10="مل",H10="لتر"),F10/1000,IF(AND(G10="لتر",H10="مل"),F10*1000,"خطأ وحدة")))))) -> 1 | J10: 0 | K10: نعم | L10: =IFERROR(VLOOKUP(D10,'مراجع الوصفات'!$F$2:$I$253,4,FALSE),"") -> 3000 | M10: =IF(OR(I10="",NOT(ISNUMBER(I10)),L10=""),"",I10*L10*(1+J10/100)) -> 3000 | O10: =IF(AND(B10="",D10="",F10=""),"",IF(A10="تجاهل","تجاهل",IF(OR(B10="",D10="",F10="",G10="",H10=""),"ناقص",IF(NOT(ISNUMBER(I10)),"خطأ وحدة",IF(OR(J10<0,J10>100),"خطأ هدر","صالح"))))) -> صالح
A11: جاهز للاستيراد | B11: هوت شوكليت بالحليب | C11: =IFERROR(VLOOKUP(B11,'مراجع الوصفات'!$A$2:$D$79,2,FALSE),"") -> hot_chocolate_milk | D11: هوت شوكليت – ظرف | E11: =IFERROR(VLOOKUP(D11,'مراجع الوصفات'!$F$2:$I$253,2,FALSE),"") -> DRK-CHOCO-SACHET | F11: 1 | G11: حصة | H11: =IFERROR(VLOOKUP(D11,'مراجع الوصفات'!$F$2:$I$253,3,FALSE),"") -> حصة | I11: =IF(OR(F11="",G11="",H11=""),"",IF(G11=H11,F11,IF(AND(G11="غ",H11="كغ"),F11/1000,IF(AND(G11="كغ",H11="غ"),F11*1000,IF(AND(G11="مل",H11="لتر"),F11/1000,IF(AND(G11="لتر",H11="مل"),F11*1000,"خطأ وحدة")))))) -> 1 | J11: 0 | K11: نعم | L11: =IFERROR(VLOOKUP(D11,'مراجع الوصفات'!$F$2:$I$253,4,FALSE),"") -> 3000 | M11: =IF(OR(I11="",NOT(ISNUMBER(I11)),L11=""),"",I11*L11*(1+J11/100)) -> 3000 | O11: =IF(AND(B11="",D11="",F11=""),"",IF(A11="تجاهل","تجاهل",IF(OR(B11="",D11="",F11="",G11="",H11=""),"ناقص",IF(NOT(ISNUMBER(I11)),"خطأ وحدة",IF(OR(J11<0,J11>100),"خطأ هدر","صالح"))))) -> صالح
A12: جاهز للاستيراد | B12: هوت شوكليت بالحليب | C12: =IFERROR(VLOOKUP(B12,'مراجع الوصفات'!$A$2:$D$79,2,FALSE),"") -> hot_chocolate_milk | D12: حليب | E12: =IFERROR(VLOOKUP(D12,'مراجع الوصفات'!$F$2:$I$253,2,FALSE),"") -> ING-DAIRY-MILK | F12: 200 | G12: مل | H12: =IFERROR(VLOOKUP(D12,'مراجع الوصفات'!$F$2:$I$253,3,FALSE),"") -> لتر | I12: =IF(OR(F12="",G12="",H12=""),"",IF(G12=H12,F12,IF(AND(G12="غ",H12="كغ"),F12/1000,IF(AND(G12="كغ",H12="غ"),F12*1000,IF(AND(G12="مل",H12="لتر"),F12/1000,IF(AND(G12="لتر",H12="مل"),F12*1000,"خطأ وحدة")))))) -> 0.2 | J12: 0 | K12: نعم | L12: =IFERROR(VLOOKUP(D12,'مراجع الوصفات'!$F$2:$I$253,4,FALSE),"") -> 15000 | M12: =IF(OR(I12="",NOT(ISNUMBER(I12)),L12=""),"",I12*L12*(1+J12/100)) -> 3000 | N12: تقدير 200مل حليب. | O12: =IF(AND(B12="",D12="",F12=""),"",IF(A12="تجاهل","تجاهل",IF(OR(B12="",D12="",F12="",G12="",H12=""),"ناقص",IF(NOT(ISNUMBER(I12)),"خطأ وحدة",IF(OR(J12<0,J12>100),"خطأ هدر","صالح"))))) -> صالح
A13: جاهز للاستيراد | B13: ماتشا بالماء | C13: =IFERROR(VLOOKUP(B13,'مراجع الوصفات'!$A$2:$D$79,2,FALSE),"") -> matcha_water | D13: ماتشا – حصة | E13: =IFERROR(VLOOKUP(D13,'مراجع الوصفات'!$F$2:$I$253,2,FALSE),"") -> DRK-MATCHA-PORTION | F13: 1 | G13: حصة | H13: =IFERROR(VLOOKUP(D13,'مراجع الوصفات'!$F$2:$I$253,3,FALSE),"") -> حصة | I13: =IF(OR(F13="",G13="",H13=""),"",IF(G13=H13,F13,IF(AND(G13="غ",H13="كغ"),F13/1000,IF(AND(G13="كغ",H13="غ"),F13*1000,IF(AND(G13="مل",H13="لتر"),F13/1000,IF(AND(G13="لتر",H13="مل"),F13*1000,"خطأ وحدة")))))) -> 1 | J13: 0 | K13: نعم | L13: =IFERROR(VLOOKUP(D13,'مراجع الوصفات'!$F$2:$I$253,4,FALSE),"") -> 4450 | M13: =IF(OR(I13="",NOT(ISNUMBER(I13)),L13=""),"",I13*L13*(1+J13/100)) -> 4450 | O13: =IF(AND(B13="",D13="",F13=""),"",IF(A13="تجاهل","تجاهل",IF(OR(B13="",D13="",F13="",G13="",H13=""),"ناقص",IF(NOT(ISNUMBER(I13)),"خطأ وحدة",IF(OR(J13<0,J13>100),"خطأ هدر","صالح"))))) -> صالح
A14: جاهز للاستيراد | B14: ماتشا لاتيه ساخن | C14: =IFERROR(VLOOKUP(B14,'مراجع الوصفات'!$A$2:$D$79,2,FALSE),"") -> hot_matcha_latte | D14: ماتشا – حصة | E14: =IFERROR(VLOOKUP(D14,'مراجع الوصفات'!$F$2:$I$253,2,FALSE),"") -> DRK-MATCHA-PORTION | F14: 1 | G14: حصة | H14: =IFERROR(VLOOKUP(D14,'مراجع الوصفات'!$F$2:$I$253,3,FALSE),"") -> حصة | I14: =IF(OR(F14="",G14="",H14=""),"",IF(G14=H14,F14,IF(AND(G14="غ",H14="كغ"),F14/1000,IF(AND(G14="كغ",H14="غ"),F14*1000,IF(AND(G14="مل",H14="لتر"),F14/1000,IF(AND(G14="لتر",H14="مل"),F14*1000,"خطأ وحدة")))))) -> 1 | J14: 0 | K14: نعم | L14: =IFERROR(VLOOKUP(D14,'مراجع الوصفات'!$F$2:$I$253,4,FALSE),"") -> 4450 | M14: =IF(OR(I14="",NOT(ISNUMBER(I14)),L14=""),"",I14*L14*(1+J14/100)) -> 4450 | O14: =IF(AND(B14="",D14="",F14=""),"",IF(A14="تجاهل","تجاهل",IF(OR(B14="",D14="",F14="",G14="",H14=""),"ناقص",IF(NOT(ISNUMBER(I14)),"خطأ وحدة",IF(OR(J14<0,J14>100),"خطأ هدر","صالح"))))) -> صالح
A15: جاهز للاستيراد | B15: ماتشا لاتيه ساخن | C15: =IFERROR(VLOOKUP(B15,'مراجع الوصفات'!$A$2:$D$79,2,FALSE),"") -> hot_matcha_latte | D15: حليب | E15: =IFERROR(VLOOKUP(D15,'مراجع الوصفات'!$F$2:$I$253,2,FALSE),"") -> ING-DAIRY-MILK | F15: 200 | G15: مل | H15: =IFERROR(VLOOKUP(D15,'مراجع الوصفات'!$F$2:$I$253,3,FALSE),"") -> لتر | I15: =IF(OR(F15="",G15="",H15=""),"",IF(G15=H15,F15,IF(AND(G15="غ",H15="كغ"),F15/1000,IF(AND(G15="كغ",H15="غ"),F15*1000,IF(AND(G15="مل",H15="لتر"),F15/1000,IF(AND(G15="لتر",H15="مل"),F15*1000,"خطأ وحدة")))))) -> 0.2 | J15: 0 | K15: نعم | L15: =IFERROR(VLOOKUP(D15,'مراجع الوصفات'!$F$2:$I$253,4,FALSE),"") -> 15000 | M15: =IF(OR(I15="",NOT(ISNUMBER(I15)),L15=""),"",I15*L15*(1+J15/100)) -> 3000 | N15: تقدير 200مل حليب. | O15: =IF(AND(B15="",D15="",F15=""),"",IF(A15="تجاهل","تجاهل",IF(OR(B15="",D15="",F15="",G15="",H15=""),"ناقص",IF(NOT(ISNUMBER(I15)),"خطأ وحدة",IF(OR(J15<0,J15>100),"خطأ هدر","صالح"))))) -> صالح
A16: جاهز للاستيراد | B16: كولا / سفن أب — كاسة | C16: =IFERROR(VLOOKUP(B16,'مراجع الوصفات'!$A$2:$D$79,2,FALSE),"") -> cola_7up_glass | D16: سوبرين سفن أب / كولا 2.25 لتر | E16: =IFERROR(VLOOKUP(D16,'مراجع الوصفات'!$F$2:$I$253,2,FALSE),"") -> DRK-SODA-SUPRIN-225 | F16: 0.111 | G16: زجاجة | H16: =IFERROR(VLOOKUP(D16,'مراجع الوصفات'!$F$2:$I$253,3,FALSE),"") -> زجاجة | I16: =IF(OR(F16="",G16="",H16=""),"",IF(G16=H16,F16,IF(AND(G16="غ",H16="كغ"),F16/1000,IF(AND(G16="كغ",H16="غ"),F16*1000,IF(AND(G16="مل",H16="لتر"),F16/1000,IF(AND(G16="لتر",H16="مل"),F16*1000,"خطأ وحدة")))))) -> 0.111 | J16: 0 | K16: نعم | L16: =IFERROR(VLOOKUP(D16,'مراجع الوصفات'!$F$2:$I$253,4,FALSE),"") -> 15000 | M16: =IF(OR(I16="",NOT(ISNUMBER(I16)),L16=""),"",I16*L16*(1+J16/100)) -> 1665 | N16: يعادل تقريباً 250مل من زجاجة 2.25 لتر. | O16: =IF(AND(B16="",D16="",F16=""),"",IF(A16="تجاهل","تجاهل",IF(OR(B16="",D16="",F16="",G16="",H16=""),"ناقص",IF(NOT(ISNUMBER(I16)),"خطأ وحدة",IF(OR(J16<0,J16>100),"خطأ هدر","صالح"))))) -> صالح
A17: جاهز للاستيراد | B17: مشروب معلب / غازي | C17: =IFERROR(VLOOKUP(B17,'مراجع الوصفات'!$A$2:$D$79,2,FALSE),"") -> canned_fizzy_drink | D17: صودا – علبة | E17: =IFERROR(VLOOKUP(D17,'مراجع الوصفات'!$F$2:$I$253,2,FALSE),"") -> DRK-SODA-CAN | F17: 1 | G17: قطعة | H17: =IFERROR(VLOOKUP(D17,'مراجع الوصفات'!$F$2:$I$253,3,FALSE),"") -> قطعة | I17: =IF(OR(F17="",G17="",H17=""),"",IF(G17=H17,F17,IF(AND(G17="غ",H17="كغ"),F17/1000,IF(AND(G17="كغ",H17="غ"),F17*1000,IF(AND(G17="مل",H17="لتر"),F17/1000,IF(AND(G17="لتر",H17="مل"),F17*1000,"خطأ وحدة")))))) -> 1 | J17: 0 | K17: نعم | L17: =IFERROR(VLOOKUP(D17,'مراجع الوصفات'!$F$2:$I$253,4,FALSE),"") | M17: =IF(OR(I17="",NOT(ISNUMBER(I17)),L17=""),"",I17*L17*(1+J17/100)) | O17: =IF(AND(B17="",D17="",F17=""),"",IF(A17="تجاهل","تجاهل",IF(OR(B17="",D17="",F17="",G17="",H17=""),"ناقص",IF(NOT(ISNUMBER(I17)),"خطأ وحدة",IF(OR(J17<0,J17>100),"خطأ هدر","صالح"))))) -> صالح
A18: جاهز للاستيراد | B18: عصير كاسة | C18: =IFERROR(VLOOKUP(B18,'مراجع الوصفات'!$A$2:$D$79,2,FALSE),"") -> juice_glass | D18: عصير فيوري 1 لتر | E18: =IFERROR(VLOOKUP(D18,'مراجع الوصفات'!$F$2:$I$253,2,FALSE),"") -> DRK-JUICE-FIORI-1L | F18: 250 | G18: مل | H18: =IFERROR(VLOOKUP(D18,'مراجع الوصفات'!$F$2:$I$253,3,FALSE),"") -> لتر | I18: =IF(OR(F18="",G18="",H18=""),"",IF(G18=H18,F18,IF(AND(G18="غ",H18="كغ"),F18/1000,IF(AND(G18="كغ",H18="غ"),F18*1000,IF(AND(G18="مل",H18="لتر"),F18/1000,IF(AND(G18="لتر",H18="مل"),F18*1000,"خطأ وحدة")))))) -> 0.25 | J18: 0 | K18: نعم | L18: =IFERROR(VLOOKUP(D18,'مراجع الوصفات'!$F$2:$I$253,4,FALSE),"") -> 15000 | M18: =IF(OR(I18="",NOT(ISNUMBER(I18)),L18=""),"",I18*L18*(1+J18/100)) -> 3750 | N18: تقدير كاسة 250مل. | O18: =IF(AND(B18="",D18="",F18=""),"",IF(A18="تجاهل","تجاهل",IF(OR(B18="",D18="",F18="",G18="",H18=""),"ناقص",IF(NOT(ISNUMBER(I18)),"خطأ وحدة",IF(OR(J18<0,J18>100),"خطأ هدر","صالح"))))) -> صالح
A19: جاهز للاستيراد | B19: عصير كبير | C19: =IFERROR(VLOOKUP(B19,'مراجع الوصفات'!$A$2:$D$79,2,FALSE),"") -> large_juice | D19: عصير فيوري 1 لتر | E19: =IFERROR(VLOOKUP(D19,'مراجع الوصفات'!$F$2:$I$253,2,FALSE),"") -> DRK-JUICE-FIORI-1L | F19: 400 | G19: مل | H19: =IFERROR(VLOOKUP(D19,'مراجع الوصفات'!$F$2:$I$253,3,FALSE),"") -> لتر | I19: =IF(OR(F19="",G19="",H19=""),"",IF(G19=H19,F19,IF(AND(G19="غ",H19="كغ"),F19/1000,IF(AND(G19="كغ",H19="غ"),F19*1000,IF(AND(G19="مل",H19="لتر"),F19/1000,IF(AND(G19="لتر",H19="مل"),F19*1000,"خطأ وحدة")))))) -> 0.4 | J19: 0 | K19: نعم | L19: =IFERROR(VLOOKUP(D19,'مراجع الوصفات'!$F$2:$I$253,4,FALSE),"") -> 15000 | M19: =IF(OR(I19="",NOT(ISNUMBER(I19)),L19=""),"",I19*L19*(1+J19/100)) -> 6000 | N19: تقدير كاسة كبيرة 400مل. | O19: =IF(AND(B19="",D19="",F19=""),"",IF(A19="تجاهل","تجاهل",IF(OR(B19="",D19="",F19="",G19="",H19=""),"ناقص",IF(NOT(ISNUMBER(I19)),"خطأ وحدة",IF(OR(J19<0,J19>100),"خطأ هدر","صالح"))))) -> صالح
A20: جاهز للاستيراد | B20: شنينة / لبن بارد | C20: =IFERROR(VLOOKUP(B20,'مراجع الوصفات'!$A$2:$D$79,2,FALSE),"") -> cold_yogurt_drink | D20: شنينة جاهزة | E20: =IFERROR(VLOOKUP(D20,'مراجع الوصفات'!$F$2:$I$253,2,FALSE),"") -> DRK-AYRAN-READY | F20: 300 | G20: مل | H20: =IFERROR(VLOOKUP(D20,'مراجع الوصفات'!$F$2:$I$253,3,FALSE),"") -> لتر | I20: =IF(OR(F20="",G20="",H20=""),"",IF(G20=H20,F20,IF(AND(G20="غ",H20="كغ"),F20/1000,IF(AND(G20="كغ",H20="غ"),F20*1000,IF(AND(G20="مل",H20="لتر"),F20/1000,IF(AND(G20="لتر",H20="مل"),F20*1000,"خطأ وحدة")))))) -> 0.3 | J20: 0 | K20: نعم | L20: =IFERROR(VLOOKUP(D20,'مراجع الوصفات'!$F$2:$I$253,4,FALSE),"") | M20: =IF(OR(I20="",NOT(ISNUMBER(I20)),L20=""),"",I20*L20*(1+J20/100)) | N20: على أساس شنينة جاهزة. | O20: =IF(AND(B20="",D20="",F20=""),"",IF(A20="تجاهل","تجاهل",IF(OR(B20="",D20="",F20="",G20="",H20=""),"ناقص",IF(NOT(ISNUMBER(I20)),"خطأ وحدة",IF(OR(J20<0,J20>100),"خطأ هدر","صالح"))))) -> صالح
A21: جاهز للاستيراد | B21: دبس وليمون | C21: =IFERROR(VLOOKUP(B21,'مراجع الوصفات'!$A$2:$D$79,2,FALSE),"") -> dibs_lemon | D21: دبس عنب | E21: =IFERROR(VLOOKUP(D21,'مراجع الوصفات'!$F$2:$I$253,2,FALSE),"") -> ING-SWEET-GRAPEMOLASSES | F21: 30 | G21: غ | H21: =IFERROR(VLOOKUP(D21,'مراجع الوصفات'!$F$2:$I$253,3,FALSE),"") -> كغ | I21: =IF(OR(F21="",G21="",H21=""),"",IF(G21=H21,F21,IF(AND(G21="غ",H21="كغ"),F21/1000,IF(AND(G21="كغ",H21="غ"),F21*1000,IF(AND(G21="مل",H21="لتر"),F21/1000,IF(AND(G21="لتر",H21="مل"),F21*1000,"خطأ وحدة")))))) -> 0.03 | J21: 0 | K21: نعم | L21: =IFERROR(VLOOKUP(D21,'مراجع الوصفات'!$F$2:$I$253,4,FALSE),"") | M21: =IF(OR(I21="",NOT(ISNUMBER(I21)),L21=""),"",I21*L21*(1+J21/100)) | N21: تقدير 30غ دبس عنب. | O21: =IF(AND(B21="",D21="",F21=""),"",IF(A21="تجاهل","تجاهل",IF(OR(B21="",D21="",F21="",G21="",H21=""),"ناقص",IF(NOT(ISNUMBER(I21)),"خطأ وحدة",IF(OR(J21<0,J21>100),"خطأ هدر","صالح"))))) -> صالح
A22: جاهز للاستيراد | B22: دبس وليمون | C22: =IFERROR(VLOOKUP(B22,'مراجع الوصفات'!$A$2:$D$79,2,FALSE),"") -> dibs_lemon | D22: ليمون | E22: =IFERROR(VLOOKUP(D22,'مراجع الوصفات'!$F$2:$I$253,2,FALSE),"") -> ING-FRT-LEMON | F22: 35 | G22: غ | H22: =IFERROR(VLOOKUP(D22,'مراجع الوصفات'!$F$2:$I$253,3,FALSE),"") -> كغ | I22: =IF(OR(F22="",G22="",H22=""),"",IF(G22=H22,F22,IF(AND(G22="غ",H22="كغ"),F22/1000,IF(AND(G22="كغ",H22="غ"),F22*1000,IF(AND(G22="مل",H22="لتر"),F22/1000,IF(AND(G22="لتر",H22="مل"),F22*1000,"خطأ وحدة")))))) -> 0.035 | J22: 0 | K22: نعم | L22: =IFERROR(VLOOKUP(D22,'مراجع الوصفات'!$F$2:$I$253,4,FALSE),"") -> 30000 | M22: =IF(OR(I22="",NOT(ISNUMBER(I22)),L22=""),"",I22*L22*(1+J22/100)) -> 1050 | N22: تقدير 35غ ليمون. | O22: =IF(AND(B22="",D22="",F22=""),"",IF(A22="تجاهل","تجاهل",IF(OR(B22="",D22="",F22="",G22="",H22=""),"ناقص",IF(NOT(ISNUMBER(I22)),"خطأ وحدة",IF(OR(J22<0,J22>100),"خطأ هدر","صالح"))))) -> صالح
A23: جاهز للاستيراد | B23: جلاب الكرمة | C23: =IFERROR(VLOOKUP(B23,'مراجع الوصفات'!$A$2:$D$79,2,FALSE),"") -> karma_jallab | D23: جلاب مركز | E23: =IFERROR(VLOOKUP(D23,'مراجع الوصفات'!$F$2:$I$253,2,FALSE),"") -> DRK-LOCAL-JALLAB | F23: 40 | G23: مل | H23: =IFERROR(VLOOKUP(D23,'مراجع الوصفات'!$F$2:$I$253,3,FALSE),"") -> لتر | I23: =IF(OR(F23="",G23="",H23=""),"",IF(G23=H23,F23,IF(AND(G23="غ",H23="كغ"),F23/1000,IF(AND(G23="كغ",H23="غ"),F23*1000,IF(AND(G23="مل",H23="لتر"),F23/1000,IF(AND(G23="لتر",H23="مل"),F23*1000,"خطأ وحدة")))))) -> 0.04 | J23: 0 | K23: نعم | L23: =IFERROR(VLOOKUP(D23,'مراجع الوصفات'!$F$2:$I$253,4,FALSE),"") | M23: =IF(OR(I23="",NOT(ISNUMBER(I23)),L23=""),"",I23*L23*(1+J23/100)) | N23: تقدير 40مل مركز؛ المكسرات خيار ولا تدخل بالوصفة الأساسية. | O23: =IF(AND(B23="",D23="",F23=""),"",IF(A23="تجاهل","تجاهل",IF(OR(B23="",D23="",F23="",G23="",H23=""),"ناقص",IF(NOT(ISNUMBER(I23)),"خطأ وحدة",IF(OR(J23<0,J23>100),"خطأ هدر","صالح"))))) -> صالح
A24: جاهز للاستيراد | B24: آيس ماتشا لاتيه | C24: =IFERROR(VLOOKUP(B24,'مراجع الوصفات'!$A$2:$D$79,2,FALSE),"") -> iced_matcha_latte | D24: ماتشا – حصة | E24: =IFERROR(VLOOKUP(D24,'مراجع الوصفات'!$F$2:$I$253,2,FALSE),"") -> DRK-MATCHA-PORTION | F24: 1 | G24: حصة | H24: =IFERROR(VLOOKUP(D24,'مراجع الوصفات'!$F$2:$I$253,3,FALSE),"") -> حصة | I24: =IF(OR(F24="",G24="",H24=""),"",IF(G24=H24,F24,IF(AND(G24="غ",H24="كغ"),F24/1000,IF(AND(G24="كغ",H24="غ"),F24*1000,IF(AND(G24="مل",H24="لتر"),F24/1000,IF(AND(G24="لتر",H24="مل"),F24*1000,"خطأ وحدة")))))) -> 1 | J24: 0 | K24: نعم | L24: =IFERROR(VLOOKUP(D24,'مراجع الوصفات'!$F$2:$I$253,4,FALSE),"") -> 4450 | M24: =IF(OR(I24="",NOT(ISNUMBER(I24)),L24=""),"",I24*L24*(1+J24/100)) -> 4450 | O24: =IF(AND(B24="",D24="",F24=""),"",IF(A24="تجاهل","تجاهل",IF(OR(B24="",D24="",F24="",G24="",H24=""),"ناقص",IF(NOT(ISNUMBER(I24)),"خطأ وحدة",IF(OR(J24<0,J24>100),"خطأ هدر","صالح"))))) -> صالح
A25: جاهز للاستيراد | B25: آيس ماتشا لاتيه | C25: =IFERROR(VLOOKUP(B25,'مراجع الوصفات'!$A$2:$D$79,2,FALSE),"") -> iced_matcha_latte | D25: حليب | E25: =IFERROR(VLOOKUP(D25,'مراجع الوصفات'!$F$2:$I$253,2,FALSE),"") -> ING-DAIRY-MILK | F25: 200 | G25: مل | H25: =IFERROR(VLOOKUP(D25,'مراجع الوصفات'!$F$2:$I$253,3,FALSE),"") -> لتر | I25: =IF(OR(F25="",G25="",H25=""),"",IF(G25=H25,F25,IF(AND(G25="غ",H25="كغ"),F25/1000,IF(AND(G25="كغ",H25="غ"),F25*1000,IF(AND(G25="مل",H25="لتر"),F25/1000,IF(AND(G25="لتر",H25="مل"),F25*1000,"خطأ وحدة")))))) -> 0.2 | J25: 0 | K25: نعم | L25: =IFERROR(VLOOKUP(D25,'مراجع الوصفات'!$F$2:$I$253,4,FALSE),"") -> 15000 | M25: =IF(OR(I25="",NOT(ISNUMBER(I25)),L25=""),"",I25*L25*(1+J25/100)) -> 3000 | N25: تقدير 200مل حليب. | O25: =IF(AND(B25="",D25="",F25=""),"",IF(A25="تجاهل","تجاهل",IF(OR(B25="",D25="",F25="",G25="",H25=""),"ناقص",IF(NOT(ISNUMBER(I25)),"خطأ وحدة",IF(OR(J25<0,J25>100),"خطأ هدر","صالح"))))) -> صالح
A26: جاهز للاستيراد | B26: آيس ماتشا لاتيه | C26: =IFERROR(VLOOKUP(B26,'مراجع الوصفات'!$A$2:$D$79,2,FALSE),"") -> iced_matcha_latte | D26: ثلج | E26: =IFERROR(VLOOKUP(D26,'مراجع الوصفات'!$F$2:$I$253,2,FALSE),"") -> DRK-ICE | F26: 150 | G26: غ | H26: =IFERROR(VLOOKUP(D26,'مراجع الوصفات'!$F$2:$I$253,3,FALSE),"") -> كغ | I26: =IF(OR(F26="",G26="",H26=""),"",IF(G26=H26,F26,IF(AND(G26="غ",H26="كغ"),F26/1000,IF(AND(G26="كغ",H26="غ"),F26*1000,IF(AND(G26="مل",H26="لتر"),F26/1000,IF(AND(G26="لتر",H26="مل"),F26*1000,"خطأ وحدة")))))) -> 0.15 | J26: 0 | K26: نعم | L26: =IFERROR(VLOOKUP(D26,'مراجع الوصفات'!$F$2:$I$253,4,FALSE),"") -> 4000 | M26: =IF(OR(I26="",NOT(ISNUMBER(I26)),L26=""),"",I26*L26*(1+J26/100)) -> 600 | N26: تقدير 150غ ثلج. | O26: =IF(AND(B26="",D26="",F26=""),"",IF(A26="تجاهل","تجاهل",IF(OR(B26="",D26="",F26="",G26="",H26=""),"ناقص",IF(NOT(ISNUMBER(I26)),"خطأ وحدة",IF(OR(J26<0,J26>100),"خطأ هدر","صالح"))))) -> صالح
A27: جاهز للاستيراد | B27: كاسة الواجب — متّة مشاريب | C27: =IFERROR(VLOOKUP(B27,'مراجع الوصفات'!$A$2:$D$79,2,FALSE),"") -> wajib_cup_mate | D27: متة | E27: =IFERROR(VLOOKUP(D27,'مراجع الوصفات'!$F$2:$I$253,2,FALSE),"") -> DRK-MATE-YERBA | F27: 25 | G27: غ | H27: =IFERROR(VLOOKUP(D27,'مراجع الوصفات'!$F$2:$I$253,3,FALSE),"") -> كغ | I27: =IF(OR(F27="",G27="",H27=""),"",IF(G27=H27,F27,IF(AND(G27="غ",H27="كغ"),F27/1000,IF(AND(G27="كغ",H27="غ"),F27*1000,IF(AND(G27="مل",H27="لتر"),F27/1000,IF(AND(G27="لتر",H27="مل"),F27*1000,"خطأ وحدة")))))) -> 0.025 | J27: 0 | K27: نعم | L27: =IFERROR(VLOOKUP(D27,'مراجع الوصفات'!$F$2:$I$253,4,FALSE),"") | M27: =IF(OR(I27="",NOT(ISNUMBER(I27)),L27=""),"",I27*L27*(1+J27/100)) | N27: تقدير 25غ متّة للكاسة. | O27: =IF(AND(B27="",D27="",F27=""),"",IF(A27="تجاهل","تجاهل",IF(OR(B27="",D27="",F27="",G27="",H27=""),"ناقص",IF(NOT(ISNUMBER(I27)),"خطأ وحدة",IF(OR(J27<0,J27>100),"خطأ هدر","صالح"))))) -> صالح
A28: جاهز للاستيراد | B28: متّة طاولة | C28: =IFERROR(VLOOKUP(B28,'مراجع الوصفات'!$A$2:$D$79,2,FALSE),"") -> table_mate | D28: متة | E28: =IFERROR(VLOOKUP(D28,'مراجع الوصفات'!$F$2:$I$253,2,FALSE),"") -> DRK-MATE-YERBA | F28: 50 | G28: غ | H28: =IFERROR(VLOOKUP(D28,'مراجع الوصفات'!$F$2:$I$253,3,FALSE),"") -> كغ | I28: =IF(OR(F28="",G28="",H28=""),"",IF(G28=H28,F28,IF(AND(G28="غ",H28="كغ"),F28/1000,IF(AND(G28="كغ",H28="غ"),F28*1000,IF(AND(G28="مل",H28="لتر"),F28/1000,IF(AND(G28="لتر",H28="مل"),F28*1000,"خطأ وحدة")))))) -> 0.05 | J28: 0 | K28: نعم | L28: =IFERROR(VLOOKUP(D28,'مراجع الوصفات'!$F$2:$I$253,4,FALSE),"") | M28: =IF(OR(I28="",NOT(ISNUMBER(I28)),L28=""),"",I28*L28*(1+J28/100)) | N28: تقدير 50غ للطاولة. | O28: =IF(AND(B28="",D28="",F28=""),"",IF(A28="تجاهل","تجاهل",IF(OR(B28="",D28="",F28="",G28="",H28=""),"ناقص",IF(NOT(ISNUMBER(I28)),"خطأ وحدة",IF(OR(J28<0,J28>100),"خطأ هدر","صالح"))))) -> صالح
A29: جاهز للاستيراد | B29: زهرات البازلت | C29: =IFERROR(VLOOKUP(B29,'مراجع الوصفات'!$A$2:$D$79,2,FALSE),"") -> basalt_zhourat | D29: زهورات مشكلة | E29: =IFERROR(VLOOKUP(D29,'مراجع الوصفات'!$F$2:$I$253,2,FALSE),"") -> DRK-HERBAL-ZHOURAT | F29: 5 | G29: غ | H29: =IFERROR(VLOOKUP(D29,'مراجع الوصفات'!$F$2:$I$253,3,FALSE),"") -> كغ | I29: =IF(OR(F29="",G29="",H29=""),"",IF(G29=H29,F29,IF(AND(G29="غ",H29="كغ"),F29/1000,IF(AND(G29="كغ",H29="غ"),F29*1000,IF(AND(G29="مل",H29="لتر"),F29/1000,IF(AND(G29="لتر",H29="مل"),F29*1000,"خطأ وحدة")))))) -> 0.005 | J29: 0 | K29: نعم | L29: =IFERROR(VLOOKUP(D29,'مراجع الوصفات'!$F$2:$I$253,4,FALSE),"") | M29: =IF(OR(I29="",NOT(ISNUMBER(I29)),L29=""),"",I29*L29*(1+J29/100)) | N29: تقدير 5غ. | O29: =IF(AND(B29="",D29="",F29=""),"",IF(A29="تجاهل","تجاهل",IF(OR(B29="",D29="",F29="",G29="",H29=""),"ناقص",IF(NOT(ISNUMBER(I29)),"خطأ وحدة",IF(OR(J29<0,J29>100),"خطأ هدر","صالح"))))) -> صالح
A30: جاهز للاستيراد | B30: شاي تفاح وميرمية | C30: =IFERROR(VLOOKUP(B30,'مراجع الوصفات'!$A$2:$D$79,2,FALSE),"") -> apple_sage_tea | D30: شاي أحمد عادي – ظرف | E30: =IFERROR(VLOOKUP(D30,'مراجع الوصفات'!$F$2:$I$253,2,FALSE),"") -> DRK-TEA-AHMAD-BAG | F30: 1 | G30: حصة | H30: =IFERROR(VLOOKUP(D30,'مراجع الوصفات'!$F$2:$I$253,3,FALSE),"") -> حصة | I30: =IF(OR(F30="",G30="",H30=""),"",IF(G30=H30,F30,IF(AND(G30="غ",H30="كغ"),F30/1000,IF(AND(G30="كغ",H30="غ"),F30*1000,IF(AND(G30="مل",H30="لتر"),F30/1000,IF(AND(G30="لتر",H30="مل"),F30*1000,"خطأ وحدة")))))) -> 1 | J30: 0 | K30: نعم | L30: =IFERROR(VLOOKUP(D30,'مراجع الوصفات'!$F$2:$I$253,4,FALSE),"") -> 420 | M30: =IF(OR(I30="",NOT(ISNUMBER(I30)),L30=""),"",I30*L30*(1+J30/100)) -> 420 | O30: =IF(AND(B30="",D30="",F30=""),"",IF(A30="تجاهل","تجاهل",IF(OR(B30="",D30="",F30="",G30="",H30=""),"ناقص",IF(NOT(ISNUMBER(I30)),"خطأ وحدة",IF(OR(J30<0,J30>100),"خطأ هدر","صالح"))))) -> صالح
A31: جاهز للاستيراد | B31: شاي تفاح وميرمية | C31: =IFERROR(VLOOKUP(B31,'مراجع الوصفات'!$A$2:$D$79,2,FALSE),"") -> apple_sage_tea | D31: تفاح | E31: =IFERROR(VLOOKUP(D31,'مراجع الوصفات'!$F$2:$I$253,2,FALSE),"") -> ING-FRT-APPLE | F31: 50 | G31: غ | H31: =IFERROR(VLOOKUP(D31,'مراجع الوصفات'!$F$2:$I$253,3,FALSE),"") -> كغ | I31: =IF(OR(F31="",G31="",H31=""),"",IF(G31=H31,F31,IF(AND(G31="غ",H31="كغ"),F31/1000,IF(AND(G31="كغ",H31="غ"),F31*1000,IF(AND(G31="مل",H31="لتر"),F31/1000,IF(AND(G31="لتر",H31="مل"),F31*1000,"خطأ وحدة")))))) -> 0.05 | J31: 0 | K31: نعم | L31: =IFERROR(VLOOKUP(D31,'مراجع الوصفات'!$F$2:$I$253,4,FALSE),"") | M31: =IF(OR(I31="",NOT(ISNUMBER(I31)),L31=""),"",I31*L31*(1+J31/100)) | N31: تقدير 50غ تفاح. | O31: =IF(AND(B31="",D31="",F31=""),"",IF(A31="تجاهل","تجاهل",IF(OR(B31="",D31="",F31="",G31="",H31=""),"ناقص",IF(NOT(ISNUMBER(I31)),"خطأ وحدة",IF(OR(J31<0,J31>100),"خطأ هدر","صالح"))))) -> صالح
A32: جاهز للاستيراد | B32: شاي تفاح وميرمية | C32: =IFERROR(VLOOKUP(B32,'مراجع الوصفات'!$A$2:$D$79,2,FALSE),"") -> apple_sage_tea | D32: ميرمية مجففة | E32: =IFERROR(VLOOKUP(D32,'مراجع الوصفات'!$F$2:$I$253,2,FALSE),"") -> ING-HERB-SAGE | F32: 2 | G32: غ | H32: =IFERROR(VLOOKUP(D32,'مراجع الوصفات'!$F$2:$I$253,3,FALSE),"") -> كغ | I32: =IF(OR(F32="",G32="",H32=""),"",IF(G32=H32,F32,IF(AND(G32="غ",H32="كغ"),F32/1000,IF(AND(G32="كغ",H32="غ"),F32*1000,IF(AND(G32="مل",H32="لتر"),F32/1000,IF(AND(G32="لتر",H32="مل"),F32*1000,"خطأ وحدة")))))) -> 0.002 | J32: 0 | K32: نعم | L32: =IFERROR(VLOOKUP(D32,'مراجع الوصفات'!$F$2:$I$253,4,FALSE),"") | M32: =IF(OR(I32="",NOT(ISNUMBER(I32)),L32=""),"",I32*L32*(1+J32/100)) | N32: تقدير 2غ ميرمية. | O32: =IF(AND(B32="",D32="",F32=""),"",IF(A32="تجاهل","تجاهل",IF(OR(B32="",D32="",F32="",G32="",H32=""),"ناقص",IF(NOT(ISNUMBER(I32)),"خطأ وحدة",IF(OR(J32<0,J32>100),"خطأ هدر","صالح"))))) -> صالح
A33: جاهز للاستيراد | B33: عرق الريان — كأس | C33: =IFERROR(VLOOKUP(B33,'مراجع الوصفات'!$A$2:$D$79,2,FALSE),"") -> rayan_arak_glass | D33: عرق الريان | E33: =IFERROR(VLOOKUP(D33,'مراجع الوصفات'!$F$2:$I$253,2,FALSE),"") -> DRK-ALC-ARAK-RAYAN | F33: 50 | G33: مل | H33: =IFERROR(VLOOKUP(D33,'مراجع الوصفات'!$F$2:$I$253,3,FALSE),"") -> لتر | I33: =IF(OR(F33="",G33="",H33=""),"",IF(G33=H33,F33,IF(AND(G33="غ",H33="كغ"),F33/1000,IF(AND(G33="كغ",H33="غ"),F33*1000,IF(AND(G33="مل",H33="لتر"),F33/1000,IF(AND(G33="لتر",H33="مل"),F33*1000,"خطأ وحدة")))))) -> 0.05 | J33: 0 | K33: نعم | L33: =IFERROR(VLOOKUP(D33,'مراجع الوصفات'!$F$2:$I$253,4,FALSE),"") -> 52000 | M33: =IF(OR(I33="",NOT(ISNUMBER(I33)),L33=""),"",I33*L33*(1+J33/100)) -> 2600 | N33: راجع حجم الكأس الفعلي. | O33: =IF(AND(B33="",D33="",F33=""),"",IF(A33="تجاهل","تجاهل",IF(OR(B33="",D33="",F33="",G33="",H33=""),"ناقص",IF(NOT(ISNUMBER(I33)),"خطأ وحدة",IF(OR(J33<0,J33>100),"خطأ هدر","صالح"))))) -> صالح
A34: جاهز للاستيراد | B34: عرق الريان — كاراف صغير | C34: =IFERROR(VLOOKUP(B34,'مراجع الوصفات'!$A$2:$D$79,2,FALSE),"") -> rayan_arak_small_carafe | D34: عرق الريان | E34: =IFERROR(VLOOKUP(D34,'مراجع الوصفات'!$F$2:$I$253,2,FALSE),"") -> DRK-ALC-ARAK-RAYAN | F34: 250 | G34: مل | H34: =IFERROR(VLOOKUP(D34,'مراجع الوصفات'!$F$2:$I$253,3,FALSE),"") -> لتر | I34: =IF(OR(F34="",G34="",H34=""),"",IF(G34=H34,F34,IF(AND(G34="غ",H34="كغ"),F34/1000,IF(AND(G34="كغ",H34="غ"),F34*1000,IF(AND(G34="مل",H34="لتر"),F34/1000,IF(AND(G34="لتر",H34="مل"),F34*1000,"خطأ وحدة")))))) -> 0.25 | J34: 0 | K34: نعم | L34: =IFERROR(VLOOKUP(D34,'مراجع الوصفات'!$F$2:$I$253,4,FALSE),"") -> 52000 | M34: =IF(OR(I34="",NOT(ISNUMBER(I34)),L34=""),"",I34*L34*(1+J34/100)) -> 13000 | N34: راجع حجم الكاراف الفعلي. | O34: =IF(AND(B34="",D34="",F34=""),"",IF(A34="تجاهل","تجاهل",IF(OR(B34="",D34="",F34="",G34="",H34=""),"ناقص",IF(NOT(ISNUMBER(I34)),"خطأ وحدة",IF(OR(J34<0,J34>100),"خطأ هدر","صالح"))))) -> صالح
A35: جاهز للاستيراد | B35: عرق الريان — لتر طاولة | C35: =IFERROR(VLOOKUP(B35,'مراجع الوصفات'!$A$2:$D$79,2,FALSE),"") -> rayan_arak_table_liter | D35: عرق الريان | E35: =IFERROR(VLOOKUP(D35,'مراجع الوصفات'!$F$2:$I$253,2,FALSE),"") -> DRK-ALC-ARAK-RAYAN | F35: 1 | G35: لتر | H35: =IFERROR(VLOOKUP(D35,'مراجع الوصفات'!$F$2:$I$253,3,FALSE),"") -> لتر | I35: =IF(OR(F35="",G35="",H35=""),"",IF(G35=H35,F35,IF(AND(G35="غ",H35="كغ"),F35/1000,IF(AND(G35="كغ",H35="غ"),F35*1000,IF(AND(G35="مل",H35="لتر"),F35/1000,IF(AND(G35="لتر",H35="مل"),F35*1000,"خطأ وحدة")))))) -> 1 | J35: 0 | K35: نعم | L35: =IFERROR(VLOOKUP(D35,'مراجع الوصفات'!$F$2:$I$253,4,FALSE),"") -> 52000 | M35: =IF(OR(I35="",NOT(ISNUMBER(I35)),L35=""),"",I35*L35*(1+J35/100)) -> 52000 | O35: =IF(AND(B35="",D35="",F35=""),"",IF(A35="تجاهل","تجاهل",IF(OR(B35="",D35="",F35="",G35="",H35=""),"ناقص",IF(NOT(ISNUMBER(I35)),"خطأ وحدة",IF(OR(J35<0,J35>100),"خطأ هدر","صالح"))))) -> صالح
A36: جاهز للاستيراد | B36: بيرة خفيفة | C36: =IFERROR(VLOOKUP(B36,'مراجع الوصفات'!$A$2:$D$79,2,FALSE),"") -> light_beer | D36: بيرة خفيفة | E36: =IFERROR(VLOOKUP(D36,'مراجع الوصفات'!$F$2:$I$253,2,FALSE),"") -> DRK-ALC-BEER-LIGHT | F36: 1 | G36: زجاجة | H36: =IFERROR(VLOOKUP(D36,'مراجع الوصفات'!$F$2:$I$253,3,FALSE),"") -> زجاجة | I36: =IF(OR(F36="",G36="",H36=""),"",IF(G36=H36,F36,IF(AND(G36="غ",H36="كغ"),F36/1000,IF(AND(G36="كغ",H36="غ"),F36*1000,IF(AND(G36="مل",H36="لتر"),F36/1000,IF(AND(G36="لتر",H36="مل"),F36*1000,"خطأ وحدة")))))) -> 1 | J36: 0 | K36: نعم | L36: =IFERROR(VLOOKUP(D36,'مراجع الوصفات'!$F$2:$I$253,4,FALSE),"") -> 35000 | M36: =IF(OR(I36="",NOT(ISNUMBER(I36)),L36=""),"",I36*L36*(1+J36/100)) -> 35000 | O36: =IF(AND(B36="",D36="",F36=""),"",IF(A36="تجاهل","تجاهل",IF(OR(B36="",D36="",F36="",G36="",H36=""),"ناقص",IF(NOT(ISNUMBER(I36)),"خطأ وحدة",IF(OR(J36<0,J36>100),"خطأ هدر","صالح"))))) -> صالح
A37: جاهز للاستيراد | B37: بيرة ثقيلة | C37: =IFERROR(VLOOKUP(B37,'مراجع الوصفات'!$A$2:$D$79,2,FALSE),"") -> strong_beer | D37: بيرة ثقيلة | E37: =IFERROR(VLOOKUP(D37,'مراجع الوصفات'!$F$2:$I$253,2,FALSE),"") -> DRK-ALC-BEER-STRONG | F37: 1 | G37: زجاجة | H37: =IFERROR(VLOOKUP(D37,'مراجع الوصفات'!$F$2:$I$253,3,FALSE),"") -> زجاجة | I37: =IF(OR(F37="",G37="",H37=""),"",IF(G37=H37,F37,IF(AND(G37="غ",H37="كغ"),F37/1000,IF(AND(G37="كغ",H37="غ"),F37*1000,IF(AND(G37="مل",H37="لتر"),F37/1000,IF(AND(G37="لتر",H37="مل"),F37*1000,"خطأ وحدة")))))) -> 1 | J37: 0 | K37: نعم | L37: =IFERROR(VLOOKUP(D37,'مراجع الوصفات'!$F$2:$I$253,4,FALSE),"") -> 40000 | M37: =IF(OR(I37="",NOT(ISNUMBER(I37)),L37=""),"",I37*L37*(1+J37/100)) -> 40000 | O37: =IF(AND(B37="",D37="",F37=""),"",IF(A37="تجاهل","تجاهل",IF(OR(B37="",D37="",F37="",G37="",H37=""),"ناقص",IF(NOT(ISNUMBER(I37)),"خطأ وحدة",IF(OR(J37<0,J37>100),"خطأ هدر","صالح"))))) -> صالح
A38: جاهز للاستيراد | B38: لبنة وأعشاب | C38: =IFERROR(VLOOKUP(B38,'مراجع الوصفات'!$A$2:$D$79,2,FALSE),"") | D38: خبز سمون | E38: =IFERROR(VLOOKUP(D38,'مراجع الوصفات'!$F$2:$I$253,2,FALSE),"") -> ING-BREAD-SAMOON | F38: 1 | G38: قطعة | H38: =IFERROR(VLOOKUP(D38,'مراجع الوصفات'!$F$2:$I$253,3,FALSE),"") -> قطعة | I38: =IF(OR(F38="",G38="",H38=""),"",IF(G38=H38,F38,IF(AND(G38="غ",H38="كغ"),F38/1000,IF(AND(G38="كغ",H38="غ"),F38*1000,IF(AND(G38="مل",H38="لتر"),F38/1000,IF(AND(G38="لتر",H38="مل"),F38*1000,"خطأ وحدة")))))) -> 1 | J38: 0 | K38: نعم | L38: =IFERROR(VLOOKUP(D38,'مراجع الوصفات'!$F$2:$I$253,4,FALSE),"") | M38: =IF(OR(I38="",NOT(ISNUMBER(I38)),L38=""),"",I38*L38*(1+J38/100)) | N38: بدّل نوع الخبز بحسب المنتج الفعلي. | O38: =IF(AND(B38="",D38="",F38=""),"",IF(A38="تجاهل","تجاهل",IF(OR(B38="",D38="",F38="",G38="",H38=""),"ناقص",IF(NOT(ISNUMBER(I38)),"خطأ وحدة",IF(OR(J38<0,J38>100),"خطأ هدر","صالح"))))) -> صالح
A39: جاهز للاستيراد | B39: لبنة وأعشاب | C39: =IFERROR(VLOOKUP(B39,'مراجع الوصفات'!$A$2:$D$79,2,FALSE),"") | D39: لبنة | E39: =IFERROR(VLOOKUP(D39,'مراجع الوصفات'!$F$2:$I$253,2,FALSE),"") -> ING-DAIRY-LABNEH | F39: 100 | G39: غ | H39: =IFERROR(VLOOKUP(D39,'مراجع الوصفات'!$F$2:$I$253,3,FALSE),"") -> كغ | I39: =IF(OR(F39="",G39="",H39=""),"",IF(G39=H39,F39,IF(AND(G39="غ",H39="كغ"),F39/1000,IF(AND(G39="كغ",H39="غ"),F39*1000,IF(AND(G39="مل",H39="لتر"),F39/1000,IF(AND(G39="لتر",H39="مل"),F39*1000,"خطأ وحدة")))))) -> 0.1 | J39: 0 | K39: نعم | L39: =IFERROR(VLOOKUP(D39,'مراجع الوصفات'!$F$2:$I$253,4,FALSE),"") | M39: =IF(OR(I39="",NOT(ISNUMBER(I39)),L39=""),"",I39*L39*(1+J39/100)) | O39: =IF(AND(B39="",D39="",F39=""),"",IF(A39="تجاهل","تجاهل",IF(OR(B39="",D39="",F39="",G39="",H39=""),"ناقص",IF(NOT(ISNUMBER(I39)),"خطأ وحدة",IF(OR(J39<0,J39>100),"خطأ هدر","صالح"))))) -> صالح
A40: جاهز للاستيراد | B40: لبنة وأعشاب | C40: =IFERROR(VLOOKUP(B40,'مراجع الوصفات'!$A$2:$D$79,2,FALSE),"") | D40: نعنع طازج | E40: =IFERROR(VLOOKUP(D40,'مراجع الوصفات'!$F$2:$I$253,2,FALSE),"") -> ING-HERB-MINT | F40: 0.05 | G40: عبوة | H40: =IFERROR(VLOOKUP(D40,'مراجع الوصفات'!$F$2:$I$253,3,FALSE),"") -> عبوة | I40: =IF(OR(F40="",G40="",H40=""),"",IF(G40=H40,F40,IF(AND(G40="غ",H40="كغ"),F40/1000,IF(AND(G40="كغ",H40="غ"),F40*1000,IF(AND(G40="مل",H40="لتر"),F40/1000,IF(AND(G40="لتر",H40="مل"),F40*1000,"خطأ وحدة")))))) -> 0.05 | J40: 0 | K40: نعم | L40: =IFERROR(VLOOKUP(D40,'مراجع الوصفات'!$F$2:$I$253,4,FALSE),"") -> 1500 | M40: =IF(OR(I40="",NOT(ISNUMBER(I40)),L40=""),"",I40*L40*(1+J40/100)) -> 75 | N40: نعنع مرفق تلقائياً مع اللبنة. | O40: =IF(AND(B40="",D40="",F40=""),"",IF(A40="تجاهل","تجاهل",IF(OR(B40="",D40="",F40="",G40="",H40=""),"ناقص",IF(NOT(ISNUMBER(I40)),"خطأ وحدة",IF(OR(J40<0,J40>100),"خطأ هدر","صالح"))))) -> صالح
...

Sheet قائمة المنتجات
A1: اسم المنتج | B1: مفتاح المنتج | C1: الفئة | D1: السعر ل.س | E1: المصدر/ملاحظة
A2: قطعة كيش اليوم | B2: daily_quiche_slice | C2: الكيش | D2: 20000 | E2: Seeded Masharib menu
A3: صينية كيش كاملة | B3: whole_quiche_tray | C3: الكيش | D3: 130000 | E3: Seeded Masharib menu
A4: كومبو الصباح | B4: morning_combo | C4: كومبو الصباح | D4: 50000 | E4: Seeded Masharib menu
A5: مازا صغيرة | B5: small_mezza | C5: المازة | D5: 8000 | E5: Seeded Masharib menu
A6: مازا مفردة | B6: single_mezza | C6: المازة | D6: 10000 | E6: Seeded Masharib menu
A7: طبق 3 مازات | B7: three_mezza_plate | C7: المازة | D7: 25000 | E7: Seeded Masharib menu
A8: طبق 5 مازات | B8: five_mezza_plate | C8: المازة | D8: 40000 | E8: Seeded Masharib menu
A9: شاي عادي | B9: regular_tea | C9: مشروبات ساخنة | D9: 4000 | E9: Seeded Masharib menu
A10: شاي مع نعنع | B10: mint_tea | C10: مشروبات ساخنة | D10: 5000 | E10: Seeded Masharib menu
A11: شاي مع ميرمية | B11: sage_tea | C11: مشروبات ساخنة | D11: 5000 | E11: Seeded Masharib menu
A12: شاي إيرل غراي | B12: earl_grey_tea | C12: مشروبات ساخنة | D12: 6000 | E12: Seeded Masharib menu
A13: شاي فواكه / منكه | B13: fruit_flavored_tea | C13: مشروبات ساخنة | D13: 7000 | E13: Seeded Masharib menu
... A42: لتر عرق + طبق 4 مازات | B42: arak_liter_four_mezza | C42: مناسبات فقط | D42: 155000 | E42: Seeded Masharib menu
A43: لبنة وأعشاب | C43: سندويشات هَب | E43: Project product; match by exact Arabic name
A44: زيت وزعتر | C44: سندويشات هَب | E44: Project product; match by exact Arabic name
A45: محمّرة | C45: سندويشات هَب | E45: Project product; match by exact Arabic name
A46: الجبنة البلدية | C46: سندويشات هَب | E46: Project product; match by exact Arabic name
A47: شلل مشوية | C47: سندويشات هَب | E47: Project product; missing inventory item
A48: قشقوان محمصة | C48: سندويشات هَب | E48: Project product; missing inventory item
A49: بيض وجبنة | C49: سندويشات هَب | E49: Project product; match by exact Arabic name
A50: مرتديلا هَب | C50: سندويشات هَب | E50: Project product; missing inventory item
A51: حبش مدخن | C51: سندويشات هَب | E51: Project product; missing inventory item
A52: تونة متوسطية | C52: سندويشات هَب | E52: Project product; missing inventory item
A53: دجاج وثوم | C53: سندويشات هَب | E53: Project product; match by exact Arabic name
A54: دجاج حار | C54: سندويشات هَب | E54: Project product; match by exact Arabic name
... A79: شوت زيتونة وتاباسكو | C79: مشروبات كحولية | E79: Project product; match by exact Arabic name

Sheet دليل الوصفات
A1: دليل تعبئة واستيراد وصفات المنتجات
A3: الفكرة | B3: سطر واحد لكل مادة مخزون داخل كل منتج. اختر المنتج والمادة من القوائم، وأدخل الكمية بوحدة سهلة مثل غ أو مل؛ يحوّل الملف الكمية تلقائياً إلى وحدة المخزون.
A4: حالة الاستيراد | B4: لن يُستورد إلا السطر الذي حالته «جاهز للاستيراد» وتحققه «صالح». الوصفات المبدئية في الملف موسومة غالباً «بحاجة مراجعة» لحمايتك من إدخال تقديرات غير مؤكدة.
A5: مفتاح المنتج | B5: يُجلب تلقائياً للمنتجات المزروعة في النظام. عند غيابه، يجب أن يطابق المستورد المنتج بالاسم العربي المطابق تماماً وبشرط أن يكون فريداً.
A6: الكمية المدخلة | B6: اكتب الكمية لكل وحدة مباعة من المنتج، لا كمية الدفعة الكاملة.
A7: التحويل التلقائي | B7: الملف يحوّل فقط غ↔كغ ومل↔لتر. القطعة/العبوة/الزجاجة/الحصة يجب أن تطابق وحدة المخزون نفسها.
A8: نسبة الهدر | B8: تؤثر في حساب الكلفة فقط حالياً؛ خصم المخزون في الكود الحالي يستخدم الكمية الأساسية دون إضافة الهدر. لذلك لا تعتمد على نسبة الهدر لزيادة الخصم الفعلي.
A9: الماء | B9: لا تضف الماء ما لم ترغب فعلياً بتتبعه كمادة مخزون.
A10: التغليف | B10: لا تضف تغليف السفري إلى الوصفة الأساسية عندما يُستخدم فقط لبعض الطلبات؛ الوصفة تُخصم لكل عملية بيع بغض النظر عن داخل المكان أو سفري.
A11: الخيارات | B11: المنتجات التي تتغير بالكامل حسب خيار مثل نوع المازا أو ترقية المشروب لا يدعم نموذج الوصفة الحالي وصفة مختلفة لكل خيار. الأفضل إنشاء المنتجات كعناصر مستقلة أو إضافة نموذج وصفات للخيارات.
A12: التكرار | B12: يجب ألا يتكرر نفس المنتج + مادة المخزون + وحدة القياس؛ قاعدة البيانات تمنع التكرار.
A13: الكلفة | B13: كلفة السطر = الكمية الموحّدة × كلفة وحدة المخزون × (1 + الهدر%). تبقى فارغة عندما لا توجد كلفة للمادة.
A14: الاستيراد المقترح | B14: استخدم product key إن وجد، وإلا الاسم العربي الفريد. استخدم كود مادة المخزون دائماً. اقرأ الكمية الموحّدة ووحدة المخزون، وليس الكمية المدخلة مباشرة.
... A20: قائمة منتجات مشاريب المزروعة | B20: https://github.com/Maximad/hub/blob/main/core/management/commands/seed_masharib_menu.py

Sheet مواد ناقصة للوصفات
A1: المادة الناقصة | B1: سبب الإضافة | C1: الوحدة المقترحة | D1: المنتجات المرتبطة | E1: ملاحظة
A2: جبنة قشقوان | B2: مكوّن مباشر غير موجود في قائمة المخزون | C2: كغ | D2: قشقوان محمصة | E2: أضفها قبل استيراد الوصفة.
A3: جبنة شلل / مشللة | B3: مكوّن مباشر غير موجود في قائمة المخزون | C3: كغ | D3: شلل مشوية | E3: استخدم الاسم المحلي النهائي المعتمد.
A4: مرتديلا | B4: مكوّن مباشر غير موجود في قائمة المخزون | C4: كغ | D4: مرتديلا هَب
A5: حبش مدخن | B5: مكوّن مباشر غير موجود في قائمة المخزون | C5: كغ | D5: حبش مدخن
A6: تونة معلبة | B6: مكوّن مباشر غير موجود في قائمة المخزون | C6: كغ أو عبوة | D6: تونة متوسطية | E6: يفضل كغ إن كانت الكلفة والخصم بالوزن.
A7: ثومية / صوص ثوم | B7: أفضل من تركيب الصوص من اللبنة والثوم في كل وصفة | C7: كغ | D7: دجاج وثوم، سندويشات أخرى | E7: يمكن إنتاجها كدفعة تحضير ومادة مخزون ناتجة.
A8: مايونيز بالوزن | B8: الوحدة الحالية عبوة تجعل الحصة كسر عبوة غير واضح | C8: كغ | D8: دجاج حار، سندويشات | E8: إما تغيير وحدة مادة المايونيز أو إنشاء مادة جديدة بوحدة كغ.
A9: مخلل بالوزن | B9: الوحدة الحالية عبوة تجعل الحصة كسر عبوة غير واضح | C9: كغ | D9: السندويشات والمازات | E9: يفضل مادة منفصلة بالوزن للخصم الدقيق.

Sheet مراجع الوصفات
A1: اسم المنتج | B1: مفتاح المنتج | C1: الفئة | D1: السعر | F1: مادة المخزون | G1: كود المخزون | H1: وحدة المخزون | I1: كلفة الوحدة
A2: قطعة كيش اليوم | B2: daily_quiche_slice | C2: الكيش | D2: 20000 | F2: بطاطا | G2: ING-VEG-POTATO | H2: كغ | I2: 7000
A3: صينية كيش كاملة | B3: whole_quiche_tray | C3: الكيش | D3: 130000 | F3: بصل | G3: ING-VEG-ONION | H3: كغ | I3: 12000
A4: كومبو الصباح | B4: morning_combo | C4: كومبو الصباح | D4: 50000 | F4: كوسا | G4: ING-VEG-ZUCCHINI | H4: كغ | I4: 8000
A5: مازا صغيرة | B5: small_mezza | C5: المازة | D5: 8000 | F5: ليمون | G5: ING-FRT-LEMON | H5: كغ | I5: 30000
A6: مازا مفردة | B6: single_mezza | C6: المازة | D6: 10000 | F6: بندورة | G6: ING-VEG-TOMATO | H6: كغ | I6: 9000
A7: طبق 3 مازات | B7: three_mezza_plate | C7: المازة | D7: 25000 | F7: فاصوليا خضراء | G7: ING-VEG-GREENBEAN | H7: كغ | I7: 15500
A8: طبق 5 مازات | B8: five_mezza_plate | C8: المازة | D8: 40000 | F8: فجل | G8: ING-VEG-RADISH | H8: عبوة | I8: 2000
A9: شاي عادي | B9: regular_tea | C9: مشروبات ساخنة | D9: 4000 | F9: باذنجان | G9: ING-VEG-EGGPLANT | H9: كغ | I9: 5000
A10: شاي مع نعنع | B10: mint_tea | C10: مشروبات ساخنة | D10: 5000 | F10: فليفلة حارة | G10: ING-VEG-HOTPEPPER | H10: كغ | I10: 10000
A11: شاي مع ميرمية | B11: sage_tea | C11: مشروبات ساخنة | D11: 5000 | F11: فليفلة حلوة | G11: ING-VEG-BELLPEPPER | H11: كغ | I11: 9000
A12: شاي إيرل غراي | B12: earl_grey_tea | C12: مشروبات ساخنة | D12: 6000 | F12: خيار / بعجور | G12: ING-VEG-CUCUMBER | H12: كغ | I12: 5000
A13: شاي فواكه / منكه | B13: fruit_flavored_tea | C13: مشروبات ساخنة | D13: 7000 | F13: بازيلا خضراء | G13: ING-VEG-GREENPEAS | H13: كغ | I13: 8000
... A17: ماتشا بالماء | B17: matcha_water | C17: مشروبات ساخنة | D17: 14000 | F17: جزر | G17: ING-VEG-CARROT | H17: كغ | I17: 9000
A18: ماتشا لاتيه ساخن | B18: hot_matcha_latte | C18: مشروبات ساخنة | D18: 20000 | F18: شمندر | G18: ING-VEG-BEET | H18: كغ
A19: كولا / سفن أب — كاسة | B19: cola_7up_glass | C19: مشروبات باردة | D19: 6000 | F19: سبانخ | G19: ING-VEG-SPINACH | H19: كغ
A20: مشروب معلب / غازي | B20: canned_fizzy_drink | C20: مشروبات باردة | D20: 9000 | F20: كرفس | G20: ING-HERB-CELERY | H20: عبوة
A21: عصير كاسة | B21: juice_glass | C21: مشروبات باردة | D21: 8000 | F21: بصل أخضر | G21: ING-HERB-SPRINGONION | H21: عبوة
A22: عصير كبير | B22: large_juice | C22: مشروبات باردة | D22: 12000 | F22: ثوم طازج | G22: ING-VEG-GARLIC | H22: كغ | I22: 8000
A23: شنينة / لبن بارد | B23: cold_yogurt_drink | C23: مشروبات باردة | D23: 10000 | F23: فطر طازج | G23: ING-VEG-MUSHROOM | H23: كغ
A24: دبس وليمون | B24: dibs_lemon | C24: مشروبات باردة | D24: 12000 | F24: ذرة حلوة | G24: ING-VEG-SWEETCORN | H24: كغ
A25: جلاب الكرمة | B25: karma_jallab | C25: مشروبات باردة | D25: 15000 | F25: عرانيس ذرة | G25: ING-VEG-CORNCOB | H25: قطعة
A26: آيس ماتشا لاتيه | B26: iced_matcha_latte | C26: مشروبات باردة | D26: 24000 | F26: ورق عنب | G26: ING-VEG-GRAPELEAF | H26: كغ
A27: ماتشا سبيشال | B27: matcha_special | C27: مشروبات باردة | D27: 28000 | F27: نعنع طازج | G27: ING-HERB-MINT | H27: عبوة | I27: 1500
A28: كاسة الواجب — متّة مشاريب | B28: wajib_cup_mate | C28: مشروبات توقيع | D28: 12000 | F28: بقدونس | G28: ING-HERB-PARSLEY | H28: عبوة | I28: 1500
A29: متّة طاولة | B29: table_mate | C29: مشروبات توقيع | D29: 25000 | F29: كزبرة خضراء | G29: ING-HERB-CILANTRO | H29: عبوة
A30: زهرات البازلت | B30: basalt_zhourat | C30: مشروبات توقيع | D30: 8000 | F30: حبق / ريحان | G30: ING-HERB-BASIL | H30: عبوة
A31: شاي تفاح وميرمية | B31: apple_sage_tea | C31: مشروبات توقيع | D31: 10000 | F31: زعتر بري طازج | G31: ING-HERB-WILDTHYME | H31: عبوة | I31: 3000
A32: صينية كيش + طبق 5 مازات | B32: quiche_five_mezza_tray | C32: صواني وطلبات طاولة | D32: 160000 | F32: ترخون | G32: ING-HERB-TARRAGON | H32: عبوة | I32: 3000
A33: صينية كيش + طبق 7 مازات | B33: quiche_seven_mezza_tray | C33: صواني وطلبات طاولة | D33: 175000 | F33: شبت | G33: ING-HERB-DILL | H33: عبوة
A34: طبق 7 مازات كبير | B34: large_seven_mezza_plate | C34: صواني وطلبات طاولة | D34: 55000 | F34: تفاح | G34: ING-FRT-APPLE | H34: كغ
A35: عرق الريان — كأس | B35: rayan_arak_glass | C35: مناسبات فقط | D35: 12000 | F35: بطيخ أحمر | G35: ING-FRT-WATERMELON | H35: كغ
A36: عرق الريان — كاراف صغير | B36: rayan_arak_small_carafe | C36: مناسبات فقط | D36: 45000 | F36: رمان | G36: ING-FRT-POMEGRANATE | H36: كغ
A37: عرق الريان — لتر طاولة | B37: rayan_arak_table_liter | C37: مناسبات فقط | D37: 120000 | F37: برتقال | G37: ING-FRT-ORANGE | H37: كغ
A38: بيرة خفيفة | B38: light_beer | C38: مناسبات فقط | D38: 45000 | F38: موز | G38: ING-FRT-BANANA | H38: كغ
A39: بيرة ثقيلة | B39: strong_beer | C39: مناسبات فقط | D39: 50000 | F39: فريز | G39: ING-FRT-STRAWBERRY | H39: كغ
A40: كأس عرق + مازتين | B40: arak_glass_two_mezza | C40: مناسبات فقط | D40: 32000 | F40: مشمش | G40: ING-FRT-APRICOT | H40: كغ
A41: كاراف عرق صغير + 3 مازات | B41: small_arak_carafe_three_mezza | C41: مناسبات فقط | D41: 70000 | F41: تين | G41: ING-FRT-FIG | H41: كغ
A42: لتر عرق + طبق 4 مازات | B42: arak_liter_four_mezza | C42: مناسبات فقط | D42: 155000 | F42: عنب | G42: ING-FRT-GRAPES | H42: كغ
A43: لبنة وأعشاب | C43: سندويشات هَب | F43: لبن مبستر | G43: ING-DAIRY-YOGURT-PAST | H43: كغ | I43: 15000
...
